2024-05-07 15:16:24,267 - py.warnings - WARNING - C:\Users\paofu\Envs\django-env\Lib\site-packages\celery\worker\consumer\consumer.py:508: CPendingDeprecationWarning: The broker_connection_retry configuration setting will no longer determine
whether broker connection retries are made during startup in Celery 6.0 and above.
If you wish to retain the existing behavior for retrying connections on startup,
you should set broker_connection_retry_on_startup to True.
  warnings.warn(

2024-05-07 15:16:24,306 - celery.worker.consumer.connection - INFO - Connected to redis://127.0.0.1:6379/1
2024-05-07 15:16:24,307 - py.warnings - WARNING - C:\Users\paofu\Envs\django-env\Lib\site-packages\celery\worker\consumer\consumer.py:508: CPendingDeprecationWarning: The broker_connection_retry configuration setting will no longer determine
whether broker connection retries are made during startup in Celery 6.0 and above.
If you wish to retain the existing behavior for retrying connections on startup,
you should set broker_connection_retry_on_startup to True.
  warnings.warn(

2024-05-07 15:16:24,322 - celery.worker.consumer.mingle - INFO - mingle: searching for neighbors
2024-05-07 15:16:25,345 - celery.worker.consumer.mingle - INFO - mingle: all alone
2024-05-07 15:16:25,371 - py.warnings - WARNING - C:\Users\paofu\Envs\django-env\Lib\site-packages\celery\worker\consumer\consumer.py:508: CPendingDeprecationWarning: The broker_connection_retry configuration setting will no longer determine
whether broker connection retries are made during startup in Celery 6.0 and above.
If you wish to retain the existing behavior for retrying connections on startup,
you should set broker_connection_retry_on_startup to True.
  warnings.warn(

2024-05-07 15:16:25,386 - celery.worker.pidbox - INFO - pidbox: Connected to redis://127.0.0.1:6379/1.
2024-05-07 15:16:25,389 - celery.apps.worker - INFO - celery@thinkbook ready.
2024-05-07 15:16:25,393 - celery.worker.consumer.consumer - ERROR - Received unregistered task of type 'send_mail_task'.
The message has been ignored and discarded.

Did you remember to import the module containing this task?
Or maybe you're using relative imports?

Please see
https://docs.celeryq.dev/en/latest/internals/protocol.html
for more information.

The full contents of the message body was:
b'[["970138074@qq.com", "\\u3010\\u77e5\\u4e86\\u8bfe\\u5802\\u3011\\u6fc0\\u6d3b\\u8d26\\u53f7", "\\u8bf7\\u70b9\\u51fb\\u4ee5\\u4e0b\\u94fe\\u63a5\\u6fc0\\u6d3b\\u8d26\\u53f7\\uff1ahttp://localhost:8000/staff/active?token=wZRM9NHd8R+7nbMsPWmXbkPJYR92rTLIR82OAPaDIBucZ+RVqZ6VlIjxa2bFxYEs"], {}, {"callbacks": null, "errbacks": null, "chain": null, "chord": null}]' (340b)

The full contents of the message headers:
{'lang': 'py', 'task': 'send_mail_task', 'id': '87fa3100-918e-40f5-a99f-78d72ebaa445', 'shadow': None, 'eta': None, 'expires': None, 'group': None, 'group_index': None, 'retries': 0, 'timelimit': [None, None], 'root_id': '87fa3100-918e-40f5-a99f-78d72ebaa445', 'parent_id': None, 'argsrepr': "('970138074@qq.com', '【知了课堂】激活账号', '请点击以下链接激活账号：http://localhost:8000/staff/active?token=wZRM9NHd8R+7nbMsPWmXbkPJYR92rTLIR82OAPaDIBucZ+RVqZ6VlIjxa2bFxYEs')", 'kwargsrepr': '{}', 'origin': 'gen18024@thinkbook', 'ignore_result': False, 'replaced_task_nesting': 0, 'stamped_headers': None, 'stamps': {}, 'redelivered': True}

The delivery info for this task is:
{'exchange': '', 'routing_key': 'celery', 'redelivered': True}
Traceback (most recent call last):
  File "C:\Users\paofu\Envs\django-env\Lib\site-packages\celery\worker\consumer\consumer.py", line 659, in on_task_received
    strategy = strategies[type_]
               ~~~~~~~~~~^^^^^^^
KeyError: 'send_mail_task'
2024-05-07 15:16:25,432 - celery.worker.consumer.consumer - ERROR - Received unregistered task of type 'send_mail_task'.
The message has been ignored and discarded.

Did you remember to import the module containing this task?
Or maybe you're using relative imports?

Please see
https://docs.celeryq.dev/en/latest/internals/protocol.html
for more information.

The full contents of the message body was:
b'[["970138074@qq.com", "\\u3010\\u77e5\\u4e86\\u8bfe\\u5802\\u3011\\u6fc0\\u6d3b\\u8d26\\u53f7", "\\u8bf7\\u70b9\\u51fb\\u4ee5\\u4e0b\\u94fe\\u63a5\\u6fc0\\u6d3b\\u8d26\\u53f7\\uff1ahttp://localhost:8000/staff/active?token=kODwHn28O8x/fhj2788VIqIOCo+bJe/LOPFQiuycj1/oM6hj4+aqmLaaZ69dVbcs"], {}, {"callbacks": null, "errbacks": null, "chain": null, "chord": null}]' (340b)

The full contents of the message headers:
{'lang': 'py', 'task': 'send_mail_task', 'id': '9b491ab8-1fc9-4a59-9e1d-23b9193d489b', 'shadow': None, 'eta': None, 'expires': None, 'group': None, 'group_index': None, 'retries': 0, 'timelimit': [None, None], 'root_id': '9b491ab8-1fc9-4a59-9e1d-23b9193d489b', 'parent_id': None, 'argsrepr': "('970138074@qq.com', '【知了课堂】激活账号', '请点击以下链接激活账号：http://localhost:8000/staff/active?token=kODwHn28O8x/fhj2788VIqIOCo+bJe/LOPFQiuycj1/oM6hj4+aqmLaaZ69dVbcs')", 'kwargsrepr': '{}', 'origin': 'gen32764@thinkbook', 'ignore_result': False, 'replaced_task_nesting': 0, 'stamped_headers': None, 'stamps': {}, 'redelivered': True}

The delivery info for this task is:
{'exchange': '', 'routing_key': 'celery', 'redelivered': True}
Traceback (most recent call last):
  File "C:\Users\paofu\Envs\django-env\Lib\site-packages\celery\worker\consumer\consumer.py", line 659, in on_task_received
    strategy = strategies[type_]
               ~~~~~~~~~~^^^^^^^
KeyError: 'send_mail_task'
2024-05-07 15:16:25,436 - celery.worker.consumer.consumer - ERROR - Received unregistered task of type 'send_mail_task'.
The message has been ignored and discarded.

Did you remember to import the module containing this task?
Or maybe you're using relative imports?

Please see
https://docs.celeryq.dev/en/latest/internals/protocol.html
for more information.

The full contents of the message body was:
b'[["970138074@qq.com", "\\u3010\\u77e5\\u4e86\\u8bfe\\u5802\\u3011\\u6fc0\\u6d3b\\u8d26\\u53f7", "\\u8bf7\\u70b9\\u51fb\\u4ee5\\u4e0b\\u94fe\\u63a5\\u6fc0\\u6d3b\\u8d26\\u53f7\\uff1ahttp://localhost:8000/staff/active?token=M/GBZqSGAtaBKoLHpUSxPoI5tM60OsP2FQ486Hgjz7A3Ty/TwZMryhOX9obdXxkF"], {}, {"callbacks": null, "errbacks": null, "chain": null, "chord": null}]' (340b)

The full contents of the message headers:
{'lang': 'py', 'task': 'send_mail_task', 'id': '0cb4791c-aecd-4f1c-90ad-f75ed282ef90', 'shadow': None, 'eta': None, 'expires': None, 'group': None, 'group_index': None, 'retries': 0, 'timelimit': [None, None], 'root_id': '0cb4791c-aecd-4f1c-90ad-f75ed282ef90', 'parent_id': None, 'argsrepr': "('970138074@qq.com', '【知了课堂】激活账号', '请点击以下链接激活账号：http://localhost:8000/staff/active?token=M/GBZqSGAtaBKoLHpUSxPoI5tM60OsP2FQ486Hgjz7A3Ty/TwZMryhOX9obdXxkF')", 'kwargsrepr': '{}', 'origin': 'gen9228@thinkbook', 'ignore_result': False, 'replaced_task_nesting': 0, 'stamped_headers': None, 'stamps': {}, 'redelivered': True}

The delivery info for this task is:
{'exchange': '', 'routing_key': 'celery', 'redelivered': True}
Traceback (most recent call last):
  File "C:\Users\paofu\Envs\django-env\Lib\site-packages\celery\worker\consumer\consumer.py", line 659, in on_task_received
    strategy = strategies[type_]
               ~~~~~~~~~~^^^^^^^
KeyError: 'send_mail_task'
2024-05-07 15:16:25,441 - celery.worker.strategy - INFO - Task oaback.celery.debug_task[c0aae16b-1046-487d-855b-96c4f81151aa] received
2024-05-07 15:16:25,442 - celery.redirected - WARNING - Request: <Context: {'lang': 'py', 'task': 'oaback.celery.debug_task', 'id': 'c0aae16b-1046-487d-855b-96c4f81151aa', 'shadow': None, 'eta': None, 'expires': None, 'group': None, 'group_index': None, 'retries': 0, 'timelimit': [None, None], 'root_id': 'c0aae16b-1046-487d-855b-96c4f81151aa', 'parent_id': None, 'argsrepr': '()', 'kwargsrepr': '{}', 'origin': 'gen18804@thinkbook', 'ignore_result': True, 'replaced_task_nesting': 0, 'stamped_headers': None, 'stamps': {}, 'redelivered': True, 'properties': {'correlation_id': 'c0aae16b-1046-487d-855b-96c4f81151aa', 'reply_to': '16104cec-a9ce-35b1-abc7-9d4b7fd0f73d', 'delivery_mode': 2, 'delivery_info': {'exchange': '', 'routing_key': 'celery', 'redelivered': True}, 'priority': 0, 'body_encoding': 'base64', 'delivery_tag': '978218a8-dea0-40e0-a4b7-d8df817fa4ec'}, 'reply_to': '16104cec-a9ce-35b1-abc7-9d4b7fd0f73d', 'correlation_id': 'c0aae16b-1046-487d-855b-96c4f81151aa', 'hostname': 'celery@thinkbook', 'delivery_info': {'exchange': '', 'routing_key': 'celery', 'priority': 0, 'redelivered': True}, 'args': [], 'kwargs': {}, 'is_eager': False, 'callbacks': None, 'errbacks': None, 'chain': None, 'chord': None, 'called_directly': False, 'headers': {'redelivered': True}, '_protected': 1}>
2024-05-07 15:16:25,455 - celery.app.trace - INFO - Task oaback.celery.debug_task[c0aae16b-1046-487d-855b-96c4f81151aa] succeeded in 0.0s: None
2024-05-07 15:16:25,456 - celery.worker.strategy - INFO - Task oaback.celery.debug_task[06c85885-920d-493b-b3be-764d593c69d2] received
2024-05-07 15:16:25,457 - celery.redirected - WARNING - Request: <Context: {'lang': 'py', 'task': 'oaback.celery.debug_task', 'id': '06c85885-920d-493b-b3be-764d593c69d2', 'shadow': None, 'eta': None, 'expires': None, 'group': None, 'group_index': None, 'retries': 0, 'timelimit': [None, None], 'root_id': '06c85885-920d-493b-b3be-764d593c69d2', 'parent_id': None, 'argsrepr': '()', 'kwargsrepr': '{}', 'origin': 'gen1456@thinkbook', 'ignore_result': True, 'replaced_task_nesting': 0, 'stamped_headers': None, 'stamps': {}, 'redelivered': True, 'properties': {'correlation_id': '06c85885-920d-493b-b3be-764d593c69d2', 'reply_to': 'fef5b222-4fd3-3d10-90b6-68bdde522df2', 'delivery_mode': 2, 'delivery_info': {'exchange': '', 'routing_key': 'celery', 'redelivered': True}, 'priority': 0, 'body_encoding': 'base64', 'delivery_tag': 'd54e527d-e748-4b5f-9993-655c956a71e0'}, 'reply_to': 'fef5b222-4fd3-3d10-90b6-68bdde522df2', 'correlation_id': '06c85885-920d-493b-b3be-764d593c69d2', 'hostname': 'celery@thinkbook', 'delivery_info': {'exchange': '', 'routing_key': 'celery', 'priority': 0, 'redelivered': True}, 'args': [], 'kwargs': {}, 'is_eager': False, 'callbacks': None, 'errbacks': None, 'chain': None, 'chord': None, 'called_directly': False, 'headers': {'redelivered': True}, '_protected': 1}>
2024-05-07 15:16:25,466 - celery.app.trace - INFO - Task oaback.celery.debug_task[06c85885-920d-493b-b3be-764d593c69d2] succeeded in 0.016000000000076398s: None
2024-05-07 15:16:25,468 - celery.worker.strategy - INFO - Task oaback.celery.debug_task[b713b96f-c0bc-4fbb-8501-84605a177130] received
2024-05-07 15:16:25,468 - celery.redirected - WARNING - Request: <Context: {'lang': 'py', 'task': 'oaback.celery.debug_task', 'id': 'b713b96f-c0bc-4fbb-8501-84605a177130', 'shadow': None, 'eta': None, 'expires': None, 'group': None, 'group_index': None, 'retries': 0, 'timelimit': [None, None], 'root_id': 'b713b96f-c0bc-4fbb-8501-84605a177130', 'parent_id': None, 'argsrepr': '()', 'kwargsrepr': '{}', 'origin': 'gen35832@thinkbook', 'ignore_result': True, 'replaced_task_nesting': 0, 'stamped_headers': None, 'stamps': {}, 'redelivered': True, 'properties': {'correlation_id': 'b713b96f-c0bc-4fbb-8501-84605a177130', 'reply_to': 'eacb4144-c7f5-3e91-93c4-ea99b6b490db', 'delivery_mode': 2, 'delivery_info': {'exchange': '', 'routing_key': 'celery', 'redelivered': True}, 'priority': 0, 'body_encoding': 'base64', 'delivery_tag': 'dd870ae3-b3f0-473c-a1e4-0f2a6ea52701'}, 'reply_to': 'eacb4144-c7f5-3e91-93c4-ea99b6b490db', 'correlation_id': 'b713b96f-c0bc-4fbb-8501-84605a177130', 'hostname': 'celery@thinkbook', 'delivery_info': {'exchange': '', 'routing_key': 'celery', 'priority': 0, 'redelivered': True}, 'args': [], 'kwargs': {}, 'is_eager': False, 'callbacks': None, 'errbacks': None, 'chain': None, 'chord': None, 'called_directly': False, 'headers': {'redelivered': True}, '_protected': 1}>
2024-05-07 15:16:25,478 - celery.app.trace - INFO - Task oaback.celery.debug_task[b713b96f-c0bc-4fbb-8501-84605a177130] succeeded in 0.01499999999987267s: None
2024-05-07 15:16:25,489 - celery.worker.strategy - INFO - Task oaback.celery.debug_task[321e9893-4414-4bdf-ade2-eaf5630fa0c1] received
2024-05-07 15:16:25,493 - celery.redirected - WARNING - Request: <Context: {'lang': 'py', 'task': 'oaback.celery.debug_task', 'id': '321e9893-4414-4bdf-ade2-eaf5630fa0c1', 'shadow': None, 'eta': None, 'expires': None, 'group': None, 'group_index': None, 'retries': 0, 'timelimit': [None, None], 'root_id': '321e9893-4414-4bdf-ade2-eaf5630fa0c1', 'parent_id': None, 'argsrepr': '()', 'kwargsrepr': '{}', 'origin': 'gen36888@thinkbook', 'ignore_result': True, 'replaced_task_nesting': 0, 'stamped_headers': None, 'stamps': {}, 'redelivered': True, 'properties': {'correlation_id': '321e9893-4414-4bdf-ade2-eaf5630fa0c1', 'reply_to': '935aed68-59ca-312b-8af7-6a89c79b87e7', 'delivery_mode': 2, 'delivery_info': {'exchange': '', 'routing_key': 'celery', 'redelivered': True}, 'priority': 0, 'body_encoding': 'base64', 'delivery_tag': '399019f0-409c-46cd-96cf-01b2f48f7530'}, 'reply_to': '935aed68-59ca-312b-8af7-6a89c79b87e7', 'correlation_id': '321e9893-4414-4bdf-ade2-eaf5630fa0c1', 'hostname': 'celery@thinkbook', 'delivery_info': {'exchange': '', 'routing_key': 'celery', 'priority': 0, 'redelivered': True}, 'args': [], 'kwargs': {}, 'is_eager': False, 'callbacks': None, 'errbacks': None, 'chain': None, 'chord': None, 'called_directly': False, 'headers': {'redelivered': True}, '_protected': 1}>
2024-05-07 15:16:25,509 - celery.app.trace - INFO - Task oaback.celery.debug_task[321e9893-4414-4bdf-ade2-eaf5630fa0c1] succeeded in 0.016000000000076398s: None
2024-05-07 15:16:25,511 - celery.worker.consumer.consumer - ERROR - Received unregistered task of type 'send_mail_task'.
The message has been ignored and discarded.

Did you remember to import the module containing this task?
Or maybe you're using relative imports?

Please see
https://docs.celeryq.dev/en/latest/internals/protocol.html
for more information.

The full contents of the message body was:
b'[["hynever@qq.com", "\\u3010\\u77e5\\u4e86\\u8bfe\\u5802\\u3011\\u6fc0\\u6d3b\\u8d26\\u53f7", "\\u8bf7\\u70b9\\u51fb\\u4ee5\\u4e0b\\u94fe\\u63a5\\u6fc0\\u6d3b\\u8d26\\u53f7\\uff1ahttp://localhost:8000/staff/active?token=99gRwTUnRGXOoyi8/sUPl8iitSBOJ5l/w+owzZ7sJ5I="], {}, {"callbacks": null, "errbacks": null, "chain": null, "chord": null}]' (318b)

The full contents of the message headers:
{'lang': 'py', 'task': 'send_mail_task', 'id': '5f8ebdff-4b30-45fa-82c6-66e7d72f7928', 'shadow': None, 'eta': None, 'expires': None, 'group': None, 'group_index': None, 'retries': 0, 'timelimit': [None, None], 'root_id': '5f8ebdff-4b30-45fa-82c6-66e7d72f7928', 'parent_id': None, 'argsrepr': "('hynever@qq.com', '【知了课堂】激活账号', '请点击以下链接激活账号：http://localhost:8000/staff/active?token=99gRwTUnRGXOoyi8/sUPl8iitSBOJ5l/w+owzZ7sJ5I=')", 'kwargsrepr': '{}', 'origin': 'gen12600@thinkbook', 'ignore_result': False, 'replaced_task_nesting': 0, 'stamped_headers': None, 'stamps': {}, 'redelivered': True}

The delivery info for this task is:
{'exchange': '', 'routing_key': 'celery', 'redelivered': True}
Traceback (most recent call last):
  File "C:\Users\paofu\Envs\django-env\Lib\site-packages\celery\worker\consumer\consumer.py", line 659, in on_task_received
    strategy = strategies[type_]
               ~~~~~~~~~~^^^^^^^
KeyError: 'send_mail_task'
2024-05-07 15:16:25,514 - celery.worker.consumer.consumer - ERROR - Received unregistered task of type 'send_mail_task'.
The message has been ignored and discarded.

Did you remember to import the module containing this task?
Or maybe you're using relative imports?

Please see
https://docs.celeryq.dev/en/latest/internals/protocol.html
for more information.

The full contents of the message body was:
b'[["970138074@qq.com", "\\u3010\\u77e5\\u4e86\\u8bfe\\u5802\\u3011\\u6fc0\\u6d3b\\u8d26\\u53f7", "\\u8bf7\\u70b9\\u51fb\\u4ee5\\u4e0b\\u94fe\\u63a5\\u6fc0\\u6d3b\\u8d26\\u53f7\\uff1ahttp://localhost:8000/staff/active?token=zGsoeia87Ib21e84SzoeyQ00rsvMuXrmyWDEkCWpOAFCJSwBsEWkFloQd683dgIo"], {}, {"callbacks": null, "errbacks": null, "chain": null, "chord": null}]' (340b)

The full contents of the message headers:
{'lang': 'py', 'task': 'send_mail_task', 'id': 'c79e6a5e-b64f-46fd-bd75-e9d18b2a648f', 'shadow': None, 'eta': None, 'expires': None, 'group': None, 'group_index': None, 'retries': 0, 'timelimit': [None, None], 'root_id': 'c79e6a5e-b64f-46fd-bd75-e9d18b2a648f', 'parent_id': None, 'argsrepr': "('970138074@qq.com', '【知了课堂】激活账号', '请点击以下链接激活账号：http://localhost:8000/staff/active?token=zGsoeia87Ib21e84SzoeyQ00rsvMuXrmyWDEkCWpOAFCJSwBsEWkFloQd683dgIo')", 'kwargsrepr': '{}', 'origin': 'gen24864@thinkbook', 'ignore_result': False, 'replaced_task_nesting': 0, 'stamped_headers': None, 'stamps': {}, 'redelivered': True}

The delivery info for this task is:
{'exchange': '', 'routing_key': 'celery', 'redelivered': True}
Traceback (most recent call last):
  File "C:\Users\paofu\Envs\django-env\Lib\site-packages\celery\worker\consumer\consumer.py", line 659, in on_task_received
    strategy = strategies[type_]
               ~~~~~~~~~~^^^^^^^
KeyError: 'send_mail_task'
2024-05-07 15:16:25,518 - celery.worker.consumer.consumer - ERROR - Received unregistered task of type 'send_mail_task'.
The message has been ignored and discarded.

Did you remember to import the module containing this task?
Or maybe you're using relative imports?

Please see
https://docs.celeryq.dev/en/latest/internals/protocol.html
for more information.

The full contents of the message body was:
b'[["970138074@qq.com", "\\u3010\\u77e5\\u4e86\\u8bfe\\u5802\\u3011\\u6fc0\\u6d3b\\u8d26\\u53f7", "\\u8bf7\\u70b9\\u51fb\\u4ee5\\u4e0b\\u94fe\\u63a5\\u6fc0\\u6d3b\\u8d26\\u53f7\\uff1ahttp://localhost:8000/staff/active?token=ytv95yAtHkGHjyygUX6rIobsyWPRqoyaXyBx6Jq82BLxJVLFhtQBeIU82xJvS1JU"], {}, {"callbacks": null, "errbacks": null, "chain": null, "chord": null}]' (340b)

The full contents of the message headers:
{'lang': 'py', 'task': 'send_mail_task', 'id': 'f4e2e4b9-13b7-47c1-b0e3-de8953794f12', 'shadow': None, 'eta': None, 'expires': None, 'group': None, 'group_index': None, 'retries': 0, 'timelimit': [None, None], 'root_id': 'f4e2e4b9-13b7-47c1-b0e3-de8953794f12', 'parent_id': None, 'argsrepr': "('970138074@qq.com', '【知了课堂】激活账号', '请点击以下链接激活账号：http://localhost:8000/staff/active?token=ytv95yAtHkGHjyygUX6rIobsyWPRqoyaXyBx6Jq82BLxJVLFhtQBeIU82xJvS1JU')", 'kwargsrepr': '{}', 'origin': 'gen24864@thinkbook', 'ignore_result': False, 'replaced_task_nesting': 0, 'stamped_headers': None, 'stamps': {}, 'redelivered': True}

The delivery info for this task is:
{'exchange': '', 'routing_key': 'celery', 'redelivered': True}
Traceback (most recent call last):
  File "C:\Users\paofu\Envs\django-env\Lib\site-packages\celery\worker\consumer\consumer.py", line 659, in on_task_received
    strategy = strategies[type_]
               ~~~~~~~~~~^^^^^^^
KeyError: 'send_mail_task'
2024-05-07 15:16:25,520 - celery.worker.consumer.consumer - ERROR - Received unregistered task of type 'send_mail_task'.
The message has been ignored and discarded.

Did you remember to import the module containing this task?
Or maybe you're using relative imports?

Please see
https://docs.celeryq.dev/en/latest/internals/protocol.html
for more information.

The full contents of the message body was:
b'[["970138074@qq.com", "\\u3010\\u77e5\\u4e86\\u8bfe\\u5802\\u3011\\u6fc0\\u6d3b\\u8d26\\u53f7", "\\u8bf7\\u70b9\\u51fb\\u4ee5\\u4e0b\\u94fe\\u63a5\\u6fc0\\u6d3b\\u8d26\\u53f7\\uff1ahttp://localhost:8000/staff/active?token=l2r5fxkmPWUZhQta8p3ugG+y7UpMpfzLYo0J/HvwgwEA4Vl9XTKXKgO4/p4kiIEy"], {}, {"callbacks": null, "errbacks": null, "chain": null, "chord": null}]' (340b)

The full contents of the message headers:
{'lang': 'py', 'task': 'send_mail_task', 'id': '8533645b-502b-4e72-b0f0-3bfa5a08c799', 'shadow': None, 'eta': None, 'expires': None, 'group': None, 'group_index': None, 'retries': 0, 'timelimit': [None, None], 'root_id': '8533645b-502b-4e72-b0f0-3bfa5a08c799', 'parent_id': None, 'argsrepr': "('970138074@qq.com', '【知了课堂】激活账号', '请点击以下链接激活账号：http://localhost:8000/staff/active?token=l2r5fxkmPWUZhQta8p3ugG+y7UpMpfzLYo0J/HvwgwEA4Vl9XTKXKgO4/p4kiIEy')", 'kwargsrepr': '{}', 'origin': 'gen24864@thinkbook', 'ignore_result': False, 'replaced_task_nesting': 0, 'stamped_headers': None, 'stamps': {}, 'redelivered': True}

The delivery info for this task is:
{'exchange': '', 'routing_key': 'celery', 'redelivered': True}
Traceback (most recent call last):
  File "C:\Users\paofu\Envs\django-env\Lib\site-packages\celery\worker\consumer\consumer.py", line 659, in on_task_received
    strategy = strategies[type_]
               ~~~~~~~~~~^^^^^^^
KeyError: 'send_mail_task'
2024-05-07 15:16:25,523 - celery.worker.consumer.consumer - ERROR - Received unregistered task of type 'send_mail_task'.
The message has been ignored and discarded.

Did you remember to import the module containing this task?
Or maybe you're using relative imports?

Please see
https://docs.celeryq.dev/en/latest/internals/protocol.html
for more information.

The full contents of the message body was:
b'[["970138074@qq.com", "\\u3010\\u77e5\\u4e86\\u8bfe\\u5802\\u3011\\u6fc0\\u6d3b\\u8d26\\u53f7", "\\u8bf7\\u70b9\\u51fb\\u4ee5\\u4e0b\\u94fe\\u63a5\\u6fc0\\u6d3b\\u8d26\\u53f7\\uff1ahttp://localhost:8000/staff/active?token=90DHF9o0jooZ0wA+y9ALNVXoPkLq2ERkseL2x2l4AGX7ec0fGgNo4aJLjiFlvDIS"], {}, {"callbacks": null, "errbacks": null, "chain": null, "chord": null}]' (340b)

The full contents of the message headers:
{'lang': 'py', 'task': 'send_mail_task', 'id': 'ce718fda-2847-4db8-aa79-b12ef6a65a6d', 'shadow': None, 'eta': None, 'expires': None, 'group': None, 'group_index': None, 'retries': 0, 'timelimit': [None, None], 'root_id': 'ce718fda-2847-4db8-aa79-b12ef6a65a6d', 'parent_id': None, 'argsrepr': "('970138074@qq.com', '【知了课堂】激活账号', '请点击以下链接激活账号：http://localhost:8000/staff/active?token=90DHF9o0jooZ0wA+y9ALNVXoPkLq2ERkseL2x2l4AGX7ec0fGgNo4aJLjiFlvDIS')", 'kwargsrepr': '{}', 'origin': 'gen18024@thinkbook', 'ignore_result': False, 'replaced_task_nesting': 0, 'stamped_headers': None, 'stamps': {}, 'redelivered': True}

The delivery info for this task is:
{'exchange': '', 'routing_key': 'celery', 'redelivered': True}
Traceback (most recent call last):
  File "C:\Users\paofu\Envs\django-env\Lib\site-packages\celery\worker\consumer\consumer.py", line 659, in on_task_received
    strategy = strategies[type_]
               ~~~~~~~~~~^^^^^^^
KeyError: 'send_mail_task'
2024-05-07 15:16:25,525 - celery.worker.strategy - INFO - Task oaback.celery.debug_task[8f7c52cb-acb1-4cac-a028-0856eefdec17] received
2024-05-07 15:16:25,526 - celery.redirected - WARNING - Request: <Context: {'lang': 'py', 'task': 'oaback.celery.debug_task', 'id': '8f7c52cb-acb1-4cac-a028-0856eefdec17', 'shadow': None, 'eta': None, 'expires': None, 'group': None, 'group_index': None, 'retries': 0, 'timelimit': [None, None], 'root_id': '8f7c52cb-acb1-4cac-a028-0856eefdec17', 'parent_id': None, 'argsrepr': '()', 'kwargsrepr': '{}', 'origin': 'gen37012@thinkbook', 'ignore_result': True, 'replaced_task_nesting': 0, 'stamped_headers': None, 'stamps': {}, 'redelivered': True, 'properties': {'correlation_id': '8f7c52cb-acb1-4cac-a028-0856eefdec17', 'reply_to': '4a6ea932-9ca9-32ca-b718-91da1413a0ce', 'delivery_mode': 2, 'delivery_info': {'exchange': '', 'routing_key': 'celery', 'redelivered': True}, 'priority': 0, 'body_encoding': 'base64', 'delivery_tag': '076640a3-2872-4f68-b621-9bd5e70fe03c'}, 'reply_to': '4a6ea932-9ca9-32ca-b718-91da1413a0ce', 'correlation_id': '8f7c52cb-acb1-4cac-a028-0856eefdec17', 'hostname': 'celery@thinkbook', 'delivery_info': {'exchange': '', 'routing_key': 'celery', 'priority': 0, 'redelivered': True}, 'args': [], 'kwargs': {}, 'is_eager': False, 'callbacks': None, 'errbacks': None, 'chain': None, 'chord': None, 'called_directly': False, 'headers': {'redelivered': True}, '_protected': 1}>
2024-05-07 15:16:25,534 - celery.app.trace - INFO - Task oaback.celery.debug_task[8f7c52cb-acb1-4cac-a028-0856eefdec17] succeeded in 0.0s: None
2024-05-07 15:18:12,496 - celery.worker.strategy - INFO - Task oaback.celery.debug_task[ac5fa5d9-45a3-4745-93cb-8f0867d79231] received
2024-05-07 15:18:12,498 - celery.redirected - WARNING - Request: <Context: {'lang': 'py', 'task': 'oaback.celery.debug_task', 'id': 'ac5fa5d9-45a3-4745-93cb-8f0867d79231', 'shadow': None, 'eta': None, 'expires': None, 'group': None, 'group_index': None, 'retries': 0, 'timelimit': [None, None], 'root_id': 'ac5fa5d9-45a3-4745-93cb-8f0867d79231', 'parent_id': None, 'argsrepr': '()', 'kwargsrepr': '{}', 'origin': 'gen6876@thinkbook', 'ignore_result': True, 'replaced_task_nesting': 0, 'stamped_headers': None, 'stamps': {}, 'properties': {'correlation_id': 'ac5fa5d9-45a3-4745-93cb-8f0867d79231', 'reply_to': 'a4f20780-d91f-3d56-bf2a-701371976d07', 'delivery_mode': 2, 'delivery_info': {'exchange': '', 'routing_key': 'celery'}, 'priority': 0, 'body_encoding': 'base64', 'delivery_tag': '9b7aa485-adb7-4d79-8644-2082668a2814'}, 'reply_to': 'a4f20780-d91f-3d56-bf2a-701371976d07', 'correlation_id': 'ac5fa5d9-45a3-4745-93cb-8f0867d79231', 'hostname': 'celery@thinkbook', 'delivery_info': {'exchange': '', 'routing_key': 'celery', 'priority': 0, 'redelivered': False}, 'args': [], 'kwargs': {}, 'is_eager': False, 'callbacks': None, 'errbacks': None, 'chain': None, 'chord': None, 'called_directly': False, 'headers': None, '_protected': 1}>
2024-05-07 15:18:12,511 - celery.app.trace - INFO - Task oaback.celery.debug_task[ac5fa5d9-45a3-4745-93cb-8f0867d79231] succeeded in 0.016000000000076398s: None
2024-05-07 15:19:27,873 - py.warnings - WARNING - C:\Users\paofu\Envs\django-env\Lib\site-packages\celery\worker\consumer\consumer.py:508: CPendingDeprecationWarning: The broker_connection_retry configuration setting will no longer determine
whether broker connection retries are made during startup in Celery 6.0 and above.
If you wish to retain the existing behavior for retrying connections on startup,
you should set broker_connection_retry_on_startup to True.
  warnings.warn(

2024-05-07 15:19:27,917 - celery.worker.consumer.connection - INFO - Connected to redis://127.0.0.1:6379/1
2024-05-07 15:19:27,917 - py.warnings - WARNING - C:\Users\paofu\Envs\django-env\Lib\site-packages\celery\worker\consumer\consumer.py:508: CPendingDeprecationWarning: The broker_connection_retry configuration setting will no longer determine
whether broker connection retries are made during startup in Celery 6.0 and above.
If you wish to retain the existing behavior for retrying connections on startup,
you should set broker_connection_retry_on_startup to True.
  warnings.warn(

2024-05-07 15:19:27,919 - celery.worker.consumer.mingle - INFO - mingle: searching for neighbors
2024-05-07 15:19:28,928 - celery.worker.consumer.mingle - INFO - mingle: all alone
2024-05-07 15:19:28,938 - py.warnings - WARNING - C:\Users\paofu\Envs\django-env\Lib\site-packages\celery\worker\consumer\consumer.py:508: CPendingDeprecationWarning: The broker_connection_retry configuration setting will no longer determine
whether broker connection retries are made during startup in Celery 6.0 and above.
If you wish to retain the existing behavior for retrying connections on startup,
you should set broker_connection_retry_on_startup to True.
  warnings.warn(

2024-05-07 15:19:28,943 - celery.apps.worker - INFO - celery@thinkbook ready.
2024-05-07 15:19:28,971 - celery.worker.pidbox - INFO - pidbox: Connected to redis://127.0.0.1:6379/1.
2024-05-07 15:19:36,979 - celery.worker.strategy - INFO - Task oaback.celery.debug_task[7d66e1d1-da2f-4a46-a824-c39d3323a869] received
2024-05-07 15:19:36,980 - celery.redirected - WARNING - xxxxxxxxxxxxxxxxxxxxxxxxxxx
2024-05-07 15:19:36,994 - celery.app.trace - INFO - Task oaback.celery.debug_task[7d66e1d1-da2f-4a46-a824-c39d3323a869] succeeded in 0.016000000000076398s: None
2024-05-07 15:19:55,229 - celery.worker.strategy - INFO - Task oaback.celery.debug_task[13c06919-72ca-44e0-9f8d-f5199d3c63ff] received
2024-05-07 15:19:55,229 - celery.redirected - WARNING - xxxxxxxxxxxxxxxxxxxxxxxxxxx
2024-05-07 15:19:55,245 - celery.app.trace - INFO - Task oaback.celery.debug_task[13c06919-72ca-44e0-9f8d-f5199d3c63ff] succeeded in 0.016000000000076398s: None
2024-05-07 15:37:20,061 - py.warnings - WARNING - C:\Users\paofu\Envs\django-env\Lib\site-packages\celery\worker\consumer\consumer.py:508: CPendingDeprecationWarning: The broker_connection_retry configuration setting will no longer determine
whether broker connection retries are made during startup in Celery 6.0 and above.
If you wish to retain the existing behavior for retrying connections on startup,
you should set broker_connection_retry_on_startup to True.
  warnings.warn(

2024-05-07 15:37:20,069 - celery.worker.consumer.connection - INFO - Connected to redis://127.0.0.1:6379/1
2024-05-07 15:37:20,070 - py.warnings - WARNING - C:\Users\paofu\Envs\django-env\Lib\site-packages\celery\worker\consumer\consumer.py:508: CPendingDeprecationWarning: The broker_connection_retry configuration setting will no longer determine
whether broker connection retries are made during startup in Celery 6.0 and above.
If you wish to retain the existing behavior for retrying connections on startup,
you should set broker_connection_retry_on_startup to True.
  warnings.warn(

2024-05-07 15:37:20,075 - celery.worker.consumer.mingle - INFO - mingle: searching for neighbors
2024-05-07 15:37:21,085 - celery.worker.consumer.mingle - INFO - mingle: all alone
2024-05-07 15:37:21,142 - celery.apps.worker - INFO - celery@thinkbook ready.
2024-05-07 15:37:21,143 - py.warnings - WARNING - C:\Users\paofu\Envs\django-env\Lib\site-packages\celery\worker\consumer\consumer.py:508: CPendingDeprecationWarning: The broker_connection_retry configuration setting will no longer determine
whether broker connection retries are made during startup in Celery 6.0 and above.
If you wish to retain the existing behavior for retrying connections on startup,
you should set broker_connection_retry_on_startup to True.
  warnings.warn(

2024-05-07 15:37:21,163 - celery.worker.pidbox - INFO - pidbox: Connected to redis://127.0.0.1:6379/1.
2024-05-07 15:37:46,154 - celery.worker.strategy - INFO - Task send_mail_task[0a54d20b-9e4d-461b-902c-ae3513ecda8a] received
2024-05-07 15:37:47,339 - celery.app.trace - INFO - Task send_mail_task[0a54d20b-9e4d-461b-902c-ae3513ecda8a] succeeded in 1.1880000000001019s: None
2024-05-08 10:23:58,807 - py.warnings - WARNING - C:\Users\paofu\Envs\django-env\Lib\site-packages\celery\worker\consumer\consumer.py:508: CPendingDeprecationWarning: The broker_connection_retry configuration setting will no longer determine
whether broker connection retries are made during startup in Celery 6.0 and above.
If you wish to retain the existing behavior for retrying connections on startup,
you should set broker_connection_retry_on_startup to True.
  warnings.warn(

2024-05-08 10:23:58,839 - celery.worker.consumer.connection - INFO - Connected to redis://127.0.0.1:6379/1
2024-05-08 10:23:58,840 - py.warnings - WARNING - C:\Users\paofu\Envs\django-env\Lib\site-packages\celery\worker\consumer\consumer.py:508: CPendingDeprecationWarning: The broker_connection_retry configuration setting will no longer determine
whether broker connection retries are made during startup in Celery 6.0 and above.
If you wish to retain the existing behavior for retrying connections on startup,
you should set broker_connection_retry_on_startup to True.
  warnings.warn(

2024-05-08 10:23:58,842 - celery.worker.consumer.mingle - INFO - mingle: searching for neighbors
2024-05-08 10:23:59,852 - celery.worker.consumer.mingle - INFO - mingle: all alone
2024-05-08 10:23:59,858 - py.warnings - WARNING - C:\Users\paofu\Envs\django-env\Lib\site-packages\celery\worker\consumer\consumer.py:508: CPendingDeprecationWarning: The broker_connection_retry configuration setting will no longer determine
whether broker connection retries are made during startup in Celery 6.0 and above.
If you wish to retain the existing behavior for retrying connections on startup,
you should set broker_connection_retry_on_startup to True.
  warnings.warn(

2024-05-08 10:23:59,863 - celery.worker.pidbox - INFO - pidbox: Connected to redis://127.0.0.1:6379/1.
2024-05-08 10:23:59,868 - celery.apps.worker - INFO - celery@thinkbook ready.
2024-05-08 10:26:08,713 - celery.worker.strategy - INFO - Task send_mail_task[d730f0ba-7a8f-43f7-adeb-4fbfa766c63e] received
2024-05-08 10:26:09,783 - celery.app.trace - INFO - Task send_mail_task[d730f0ba-7a8f-43f7-adeb-4fbfa766c63e] succeeded in 1.0619999999908032s: None
2024-05-08 12:43:29,794 - celery.worker.strategy - INFO - Task send_mail_task[b2f6c084-e860-4be8-b3d6-05a3e9e7dba9] received
2024-05-08 12:43:30,911 - celery.app.trace - INFO - Task send_mail_task[b2f6c084-e860-4be8-b3d6-05a3e9e7dba9] succeeded in 1.125s: None
2024-05-10 15:51:22,692 - py.warnings - WARNING - C:\Users\paofu\Envs\django-env\Lib\site-packages\celery\worker\consumer\consumer.py:508: CPendingDeprecationWarning: The broker_connection_retry configuration setting will no longer determine
whether broker connection retries are made during startup in Celery 6.0 and above.
If you wish to retain the existing behavior for retrying connections on startup,
you should set broker_connection_retry_on_startup to True.
  warnings.warn(

2024-05-10 15:51:22,704 - celery.worker.consumer.connection - INFO - Connected to redis://127.0.0.1:6379/1
2024-05-10 15:51:22,705 - py.warnings - WARNING - C:\Users\paofu\Envs\django-env\Lib\site-packages\celery\worker\consumer\consumer.py:508: CPendingDeprecationWarning: The broker_connection_retry configuration setting will no longer determine
whether broker connection retries are made during startup in Celery 6.0 and above.
If you wish to retain the existing behavior for retrying connections on startup,
you should set broker_connection_retry_on_startup to True.
  warnings.warn(

2024-05-10 15:51:22,708 - celery.worker.consumer.mingle - INFO - mingle: searching for neighbors
2024-05-10 15:51:23,721 - celery.worker.consumer.mingle - INFO - mingle: all alone
2024-05-10 15:51:23,736 - py.warnings - WARNING - C:\Users\paofu\Envs\django-env\Lib\site-packages\celery\worker\consumer\consumer.py:508: CPendingDeprecationWarning: The broker_connection_retry configuration setting will no longer determine
whether broker connection retries are made during startup in Celery 6.0 and above.
If you wish to retain the existing behavior for retrying connections on startup,
you should set broker_connection_retry_on_startup to True.
  warnings.warn(

2024-05-10 15:51:23,748 - celery.apps.worker - INFO - celery@thinkbook ready.
2024-05-10 15:51:23,750 - celery.worker.pidbox - INFO - pidbox: Connected to redis://127.0.0.1:6379/1.
2024-05-10 15:51:45,770 - celery.worker.strategy - INFO - Task send_mail_task[c414615a-c420-4324-8fb6-1b52acfa83fc] received
2024-05-10 15:51:46,831 - celery.app.trace - INFO - Task send_mail_task[c414615a-c420-4324-8fb6-1b52acfa83fc] succeeded in 1.047000000020489s: None
2024-05-10 15:54:38,805 - celery.worker.strategy - INFO - Task send_mail_task[add5a93c-bab4-49b9-9e4c-08dc4fc76724] received
2024-05-10 15:54:39,750 - celery.app.trace - INFO - Task send_mail_task[add5a93c-bab4-49b9-9e4c-08dc4fc76724] succeeded in 0.9369999999762513s: None
2024-05-10 15:55:17,962 - celery.worker.strategy - INFO - Task send_mail_task[d4648b9b-0ae8-4d4e-acda-809953010d88] received
2024-05-10 15:55:18,938 - celery.app.trace - INFO - Task send_mail_task[d4648b9b-0ae8-4d4e-acda-809953010d88] succeeded in 0.9689999999827705s: None
2024-05-10 16:56:08,705 - py.warnings - WARNING - C:\Users\paofu\Envs\django-env\Lib\site-packages\celery\worker\consumer\consumer.py:508: CPendingDeprecationWarning: The broker_connection_retry configuration setting will no longer determine
whether broker connection retries are made during startup in Celery 6.0 and above.
If you wish to retain the existing behavior for retrying connections on startup,
you should set broker_connection_retry_on_startup to True.
  warnings.warn(

2024-05-10 16:56:08,718 - celery.worker.consumer.connection - INFO - Connected to redis://127.0.0.1:6379/1
2024-05-10 16:56:08,720 - py.warnings - WARNING - C:\Users\paofu\Envs\django-env\Lib\site-packages\celery\worker\consumer\consumer.py:508: CPendingDeprecationWarning: The broker_connection_retry configuration setting will no longer determine
whether broker connection retries are made during startup in Celery 6.0 and above.
If you wish to retain the existing behavior for retrying connections on startup,
you should set broker_connection_retry_on_startup to True.
  warnings.warn(

2024-05-10 16:56:08,723 - celery.worker.consumer.mingle - INFO - mingle: searching for neighbors
2024-05-10 16:56:09,736 - celery.worker.consumer.mingle - INFO - mingle: all alone
2024-05-10 16:56:09,740 - py.warnings - WARNING - C:\Users\paofu\Envs\django-env\Lib\site-packages\celery\worker\consumer\consumer.py:508: CPendingDeprecationWarning: The broker_connection_retry configuration setting will no longer determine
whether broker connection retries are made during startup in Celery 6.0 and above.
If you wish to retain the existing behavior for retrying connections on startup,
you should set broker_connection_retry_on_startup to True.
  warnings.warn(

2024-05-10 16:56:09,760 - celery.worker.pidbox - INFO - pidbox: Connected to redis://127.0.0.1:6379/1.
2024-05-10 16:56:09,790 - celery.apps.worker - INFO - celery@thinkbook ready.
2024-05-10 16:58:09,954 - celery.worker.strategy - INFO - Task send_mail_task[25b61eaf-6105-4b11-8e0e-8cd68f85fcfa] received
2024-05-10 16:58:11,004 - celery.app.trace - INFO - Task send_mail_task[25b61eaf-6105-4b11-8e0e-8cd68f85fcfa] succeeded in 1.062999999965541s: None
